Workbook

Sheet README
A1: LUMEN — Germany Market Entry: Price × Channel × Segment Model
A2: ATELIA × ESCP workshop, Berlin, 10–11 Sep 2026. Built from the 12 files in data/ of the case repo.
A4: HOW TO READ THIS WORKBOOK
A5: Blue text = hardcoded input (from the data room or an explicit assumption). Black = formula. Green = link to another sheet. Yellow fill = key assumption you may want to change.
A6: Every input carries a comment naming the source file. Assumptions not in the data room are flagged "ASSUMPTION" in the comment.
A8: SHEETS
A9: Inputs — unit costs, CAC, channel cost structure, segment data (survey), market sizing, home-market benchmarks, assumptions.
A10: Channel_Economics — for each of the 3 candidate prices × 3 channels: what LUMEN nets per can, unit contribution, margin %, cans needed to pay back one customer's CAC.
A11: Segment_Fit — Van Westendorp acceptance per segment at each price (two definitions: "hard ceiling" and "comfort"), plus the blended average that hides it.
A12: Payback — months to recover CAC for each price × channel × segment, using each segment's purchase frequency.
A13: Scenarios — Option A (premium, DTC + Gym first) vs Option B (volume, Retail at €1.79): side-by-side KPIs and the explicit "what you give up" lines.
A14: Volume_Estimate — Year-1 units and net revenue for a Berlin + Munich launch, transferred from home-market per-capita sales with an explicit comparability factor.
... A19: The brief's "26.7% acceptance at €2.59" is a blended average. Split by segment, Wellness Professionals and Gym-goers accept €2.19 at ~100% and buy in DTC and Gym & Office — the two channels where LUMEN nets the most per can. The price/channel trade-off is really a segment choice.

Sheet Inputs
A1: INPUTS
A3: Unit economics
A4: COGS per 330ml can (€) | B4: 0.62
A5: Blended CAC (€) | B5: 44
A6: Target LTV:CAC | B6: 3
A7: Mean LTV estimate (€) | B7: 122.1
A8: Home-market blended net price (€) | B8: 0.886
A9: Home-market blended gross margin | B9: =(B8-B4)/B8 -> 0.30022573
A11: Candidate launch prices (€) | B11: 1.79 | C11: 2.19 | D11: 2.59
A13: Channel cost structure
A14: Channel | B14: Retailer margin | C14: Distributor cut | D14: Payment % | E14: Fulfilment €/can | F14: Home-market unit mix
A15: DTC Online | B15: 0 | C15: 0 | D15: 0.029 | E15: 0.35 | F15: 0.319
A16: Gym & Office | B16: 0.2 | C16: 0 | D16: 0 | E16: 0 | F16: 0.179
A17: Retail/Grocery | B17: 0.35 | C17: 0.08 | D17: 0 | E17: 0 | F17: 0.502
A18: Net price formula: price × (1 − retailer − distributor − payment) − fulfilment. Reproduces channel_economics.csv to the cent.
A20: German customer segments (survey data)
A21: Segment | B21: Share of survey | C21: Purchases / month | D21: Intent (1–10) | E21: Prefers DTC | F21: Prefers Gym & Office | G21: Prefers Retail | H21: Accept €1.79 (hard) | I21: Accept €2.19 (hard) | J21: Accept €2.59 (hard) | K21: Source / definition
A22: Urban Wellness Professionals | B22: 0.267 | C22: 7.56 | D22: 9.12 | E22: 0.536 | F22: 0.143 | G22: 0.321 | H22: 1 | I22: 1 | J22: 1 | K22: Hard = price below "too expensive" threshold
A23: Fitness & Gym-Goers | B23: 0.198 | C23: 6.23 | D23: 7.97 | E23: 0.169 | F23: 0.446 | G23: 0.386 | H23: 1 | I23: 1 | J23: 1 | K23: Hard = price below "too expensive" threshold
A24: On-the-go Commuters | B24: 0.214 | C24: 5.87 | D24: 6.71 | E24: 0.167 | F24: 0.233 | G24: 0.6 | H24: 1 | I24: 1 | J24: 0.719 | K24: Hard = price below "too expensive" threshold
A25: Students & Budget-Conscious | B25: 0.321 | C25: 5.1 | D25: 5.5 | E25: 0.222 | F25: 0.237 | G25: 0.541 | H25: 0.98 | I25: 0.525 | J25: 0.03 | K25: Hard = price below "too expensive" threshold
A27: Segment | B27: Comfort €1.79 | C27: Comfort €2.19 | D27: Comfort €2.59
A28: Urban Wellness Professionals | B28: 1 | C28: 0.986 | D28: 0.757
A29: Fitness & Gym-Goers | B29: 1 | C29: 0.905 | D29: 0.317
A30: On-the-go Commuters | B30: 0.891 | C30: 0.344 | D30: 0
A31: Students & Budget-Conscious | B31: 0.374 | C31: 0.03 | D31: 0
A32: Comfort = price below the "expensive" threshold. Stricter than "hard". Both are shown because the gap between them IS the CMO/CFO debate.
A34: German market (Exhibit 1)
A35: Plant-based / adaptogenic sub-category 2026 (€) | B35: 2184000000
A36: Energy / focus sub-category 2026 (€) | B36: 2548000000
A37: Berlin share of market | B37: 0.18
A38: Munich share of market | B38: 0.15
A39: Berlin + Munich regional CAGR | B39: 0.09
A41: Home-market benchmarks (transfer base)
A42: Country | B42: Annualised units | C42: Population (m) | D42: Units / capita / yr
A43: Netherlands | B43: 340424 | C43: 18 | D43: =B43/(C43*1000000) -> 0.018912444
A44: Denmark | B44: 203983 | C44: 6 | D44: =B44/(C44*1000000) -> 0.033997167
A45: Sweden | B45: 255488 | C45: 10.6 | D45: =B45/(C45*1000000) -> 0.024102642
A46: Weighted units / capita / yr | D46: =SUM(B43:B45)/(SUM(C43:C45)*1000000) -> 0.023118353
A48: Launch geography & assumptions
...

Sheet Channel_Economics
A1: CHANNEL ECONOMICS — what LUMEN keeps per can
A3: Price (€) | B3: Channel | C3: Net to LUMEN (€) | D3: Contribution (€) | E3: Margin % | F3: Cans to repay CAC | G3: Check vs price_test_results | H3: Δ (should be ~0)
A4: =Inputs!B11 -> 1.79 | B4: DTC Online | C4: =A4*(1-Inputs!B15-Inputs!C15-Inputs!D15)-Inputs!E15 -> 1.38809 | D4: =C4-Inputs!$B$4 -> 0.76809 | E4: =IF(C4=0,0,D4/C4) -> 0.55334308 | F4: =IF(D4<=0,0,Inputs!$B$5/D4) -> 57.284954 | G4: 0.77 | H4: =D4-G4 -> -0.00191
A5: =Inputs!B11 -> 1.79 | B5: Gym & Office | C5: =A5*(1-Inputs!B16-Inputs!C16-Inputs!D16)-Inputs!E16 -> 1.432 | D5: =C5-Inputs!$B$4 -> 0.812 | E5: =IF(C5=0,0,D5/C5) -> 0.56703911 | F5: =IF(D5<=0,0,Inputs!$B$5/D5) -> 54.187192 | G5: 0.81 | H5: =D5-G5 -> 0.002
A6: =Inputs!B11 -> 1.79 | B6: Retail/Grocery | C6: =A6*(1-Inputs!B17-Inputs!C17-Inputs!D17)-Inputs!E17 -> 1.0203 | D6: =C6-Inputs!$B$4 -> 0.4003 | E6: =IF(C6=0,0,D6/C6) -> 0.39233559 | F6: =IF(D6<=0,0,Inputs!$B$5/D6) -> 109.91756 | G6: 0.4 | H6: =D6-G6 -> 0.0003
A7: =Inputs!C11 -> 2.19 | B7: DTC Online | C7: =A7*(1-Inputs!B15-Inputs!C15-Inputs!D15)-Inputs!E15 -> 1.77649 | D7: =C7-Inputs!$B$4 -> 1.15649 | E7: =IF(C7=0,0,D7/C7) -> 0.65099719 | F7: =IF(D7<=0,0,Inputs!$B$5/D7) -> 38.046157 | G7: 1.16 | H7: =D7-G7 -> -0.00351
A8: =Inputs!C11 -> 2.19 | B8: Gym & Office | C8: =A8*(1-Inputs!B16-Inputs!C16-Inputs!D16)-Inputs!E16 -> 1.752 | D8: =C8-Inputs!$B$4 -> 1.132 | E8: =IF(C8=0,0,D8/C8) -> 0.64611872 | F8: =IF(D8<=0,0,Inputs!$B$5/D8) -> 38.869258 | G8: 1.13 | H8: =D8-G8 -> 0.002
A9: =Inputs!C11 -> 2.19 | B9: Retail/Grocery | C9: =A9*(1-Inputs!B17-Inputs!C17-Inputs!D17)-Inputs!E17 -> 1.2483 | D9: =C9-Inputs!$B$4 -> 0.6283 | E9: =IF(C9=0,0,D9/C9) -> 0.50332452 | F9: =IF(D9<=0,0,Inputs!$B$5/D9) -> 70.03024 | G9: 0.63 | H9: =D9-G9 -> -0.0017
A10: =Inputs!D11 -> 2.59 | B10: DTC Online | C10: =A10*(1-Inputs!B15-Inputs!C15-Inputs!D15)-Inputs!E15 -> 2.16489 | D10: =C10-Inputs!$B$4 -> 1.54489 | E10: =IF(C10=0,0,D10/C10) -> 0.71361132 | F10: =IF(D10<=0,0,Inputs!$B$5/D10) -> 28.480992 | G10: 1.54 | H10: =D10-G10 -> 0.00489
A11: =Inputs!D11 -> 2.59 | B11: Gym & Office | C11: =A11*(1-Inputs!B16-Inputs!C16-Inputs!D16)-Inputs!E16 -> 2.072 | D11: =C11-Inputs!$B$4 -> 1.452 | E11: =IF(C11=0,0,D11/C11) -> 0.7007722 | F11: =IF(D11<=0,0,Inputs!$B$5/D11) -> 30.30303 | G11: 1.45 | H11: =D11-G11 -> 0.002
A12: =Inputs!D11 -> 2.59 | B12: Retail/Grocery | C12: =A12*(1-Inputs!B17-Inputs!C17-Inputs!D17)-Inputs!E17 -> 1.4763 | D12: =C12-Inputs!$B$4 -> 0.8563 | E12: =IF(C12=0,0,D12/C12) -> 0.58003116 | F12: =IF(D12<=0,0,Inputs!$B$5/D12) -> 51.383861 | G12: 0.86 | H12: =D12-G12 -> -0.0037
A14: Reading: at €2.19, a can sold online or in a gym contributes ~€1.15; the same can in a supermarket contributes €0.63. Retail is not "safe" — it is the channel where the price cut is shared with two intermediaries.

Sheet Segment_Fit
A1: SEGMENT FIT — who actually accepts each price
A3: Segment | B3: Share | C3: Hard €1.79 | D3: Hard €2.19 | E3: Hard €2.59 | F3: Comfort €1.79 | G3: Comfort €2.19 | H3: Comfort €2.59
A4: =Inputs!A22 -> Urban Wellness Professionals | B4: =Inputs!B22 -> 0.267 | C4: =Inputs!H22 -> 1 | D4: =Inputs!I22 -> 1 | E4: =Inputs!J22 -> 1 | F4: =Inputs!B28 -> 1 | G4: =Inputs!C28 -> 0.986 | H4: =Inputs!D28 -> 0.757
A5: =Inputs!A23 -> Fitness & Gym-Goers | B5: =Inputs!B23 -> 0.198 | C5: =Inputs!H23 -> 1 | D5: =Inputs!I23 -> 1 | E5: =Inputs!J23 -> 1 | F5: =Inputs!B29 -> 1 | G5: =Inputs!C29 -> 0.905 | H5: =Inputs!D29 -> 0.317
A6: =Inputs!A24 -> On-the-go Commuters | B6: =Inputs!B24 -> 0.214 | C6: =Inputs!H24 -> 1 | D6: =Inputs!I24 -> 1 | E6: =Inputs!J24 -> 0.719 | F6: =Inputs!B30 -> 0.891 | G6: =Inputs!C30 -> 0.344 | H6: =Inputs!D30 -> 0
A7: =Inputs!A25 -> Students & Budget-Conscious | B7: =Inputs!B25 -> 0.321 | C7: =Inputs!H25 -> 0.98 | D7: =Inputs!I25 -> 0.525 | E7: =Inputs!J25 -> 0.03 | F7: =Inputs!B31 -> 0.374 | G7: =Inputs!C31 -> 0.03 | H7: =Inputs!D31 -> 0
A8: Blended (survey mix) | C8: =SUMPRODUCT($B$4:$B$7,C4:C7) -> 0.99358 | D8: =SUMPRODUCT($B$4:$B$7,D4:D7) -> 0.847525 | E8: =SUMPRODUCT($B$4:$B$7,E4:E7) -> 0.628496 | F8: =SUMPRODUCT($B$4:$B$7,F4:F7) -> 0.775728 | G8: =SUMPRODUCT($B$4:$B$7,G4:G7) -> 0.525698 | H8: =SUMPRODUCT($B$4:$B$7,H4:H7) -> 0.264885
A9: Premium segments only (Wellness + Gym) | C9: =SUMPRODUCT($B$4:$B$5,C4:C5)/SUM($B$4:$B$5) -> 1 | D9: =SUMPRODUCT($B$4:$B$5,D4:D5)/SUM($B$4:$B$5) -> 1 | E9: =SUMPRODUCT($B$4:$B$5,E4:E5)/SUM($B$4:$B$5) -> 1 | F9: =SUMPRODUCT($B$4:$B$5,F4:F5)/SUM($B$4:$B$5) -> 1 | G9: =SUMPRODUCT($B$4:$B$5,G4:G5)/SUM($B$4:$B$5) -> 0.95150968 | H9: =SUMPRODUCT($B$4:$B$5,H4:H5)/SUM($B$4:$B$5) -> 0.56964516
A10: Share of survey lost at this price (hard) | C10: =1-C8 -> 0.00642 | D10: =1-D8 -> 0.152475 | E10: =1-E8 -> 0.371504
A12: Reading: the blended "comfort" line reproduces the brief's headline (~77% / 52% / 25%). Row 9 shows the same prices for the two premium segments: €2.19 is comfortable for ~95% of them. The average hides the answer.

Sheet Payback
A1: CAC PAYBACK — months to recover €44 per customer
A3: Price (€) | B3: Channel | C3: Segment | D3: Contribution / can (€) | E3: Purchases / month | F3: Cans to pay back | G3: Months
A4: =Channel_Economics!A4 -> 1.79 | B4: DTC Online | C4: =Inputs!A22 -> Urban Wellness Professionals | D4: =Channel_Economics!D4 -> 0.76809 | E4: =Inputs!C22 -> 7.56 | F4: =IF(D4<=0,0,Inputs!$B$5/D4) -> 57.284954 | G4: =IF(E4=0,0,F4/E4) -> 7.5773748
A5: =Channel_Economics!A4 -> 1.79 | B5: DTC Online | C5: =Inputs!A23 -> Fitness & Gym-Goers | D5: =Channel_Economics!D4 -> 0.76809 | E5: =Inputs!C23 -> 6.23 | F5: =IF(D5<=0,0,Inputs!$B$5/D5) -> 57.284954 | G5: =IF(E5=0,0,F5/E5) -> 9.1950166
A6: =Channel_Economics!A4 -> 1.79 | B6: DTC Online | C6: =Inputs!A24 -> On-the-go Commuters | D6: =Channel_Economics!D4 -> 0.76809 | E6: =Inputs!C24 -> 5.87 | F6: =IF(D6<=0,0,Inputs!$B$5/D6) -> 57.284954 | G6: =IF(E6=0,0,F6/E6) -> 9.7589359
A7: =Channel_Economics!A4 -> 1.79 | B7: DTC Online | C7: =Inputs!A25 -> Students & Budget-Conscious | D7: =Channel_Economics!D4 -> 0.76809 | E7: =Inputs!C25 -> 5.1 | F7: =IF(D7<=0,0,Inputs!$B$5/D7) -> 57.284954 | G7: =IF(E7=0,0,F7/E7) -> 11.232344
A8: =Channel_Economics!A5 -> 1.79 | B8: Gym & Office | C8: =Inputs!A22 -> Urban Wellness Professionals | D8: =Channel_Economics!D5 -> 0.812 | E8: =Inputs!C22 -> 7.56 | F8: =IF(D8<=0,0,Inputs!$B$5/D8) -> 54.187192 | G8: =IF(E8=0,0,F8/E8) -> 7.167618
A9: =Channel_Economics!A5 -> 1.79 | B9: Gym & Office | C9: =Inputs!A23 -> Fitness & Gym-Goers | D9: =Channel_Economics!D5 -> 0.812 | E9: =Inputs!C23 -> 6.23 | F9: =IF(D9<=0,0,Inputs!$B$5/D9) -> 54.187192 | G9: =IF(E9=0,0,F9/E9) -> 8.6977836
A10: =Channel_Economics!A5 -> 1.79 | B10: Gym & Office | C10: =Inputs!A24 -> On-the-go Commuters | D10: =Channel_Economics!D5 -> 0.812 | E10: =Inputs!C24 -> 5.87 | F10: =IF(D10<=0,0,Inputs!$B$5/D10) -> 54.187192 | G10: =IF(E10=0,0,F10/E10) -> 9.2312082
A11: =Channel_Economics!A5 -> 1.79 | B11: Gym & Office | C11: =Inputs!A25 -> Students & Budget-Conscious | D11: =Channel_Economics!D5 -> 0.812 | E11: =Inputs!C25 -> 5.1 | F11: =IF(D11<=0,0,Inputs!$B$5/D11) -> 54.187192 | G11: =IF(E11=0,0,F11/E11) -> 10.62494
A12: =Channel_Economics!A6 -> 1.79 | B12: Retail/Grocery | C12: =Inputs!A22 -> Urban Wellness Professionals | D12: =Channel_Economics!D6 -> 0.4003 | E12: =Inputs!C22 -> 7.56 | F12: =IF(D12<=0,0,Inputs!$B$5/D12) -> 109.91756 | G12: =IF(E12=0,0,F12/E12) -> 14.53936
A13: =Channel_Economics!A6 -> 1.79 | B13: Retail/Grocery | C13: =Inputs!A23 -> Fitness & Gym-Goers | D13: =Channel_Economics!D6 -> 0.4003 | E13: =Inputs!C23 -> 6.23 | F13: =IF(D13<=0,0,Inputs!$B$5/D13) -> 109.91756 | G13: =IF(E13=0,0,F13/E13) -> 17.643268
A14: =Channel_Economics!A6 -> 1.79 | B14: Retail/Grocery | C14: =Inputs!A24 -> On-the-go Commuters | D14: =Channel_Economics!D6 -> 0.4003 | E14: =Inputs!C24 -> 5.87 | F14: =IF(D14<=0,0,Inputs!$B$5/D14) -> 109.91756 | G14: =IF(E14=0,0,F14/E14) -> 18.725309
A15: =Channel_Economics!A6 -> 1.79 | B15: Retail/Grocery | C15: =Inputs!A25 -> Students & Budget-Conscious | D15: =Channel_Economics!D6 -> 0.4003 | E15: =Inputs!C25 -> 5.1 | F15: =IF(D15<=0,0,Inputs!$B$5/D15) -> 109.91756 | G15: =IF(E15=0,0,F15/E15) -> 21.552463
A16: =Channel_Economics!A7 -> 2.19 | B16: DTC Online | C16: =Inputs!A22 -> Urban Wellness Professionals | D16: =Channel_Economics!D7 -> 1.15649 | E16: =Inputs!C22 -> 7.56 | F16: =IF(D16<=0,0,Inputs!$B$5/D16) -> 38.046157 | G16: =IF(E16=0,0,F16/E16) -> 5.0325604
A17: =Channel_Economics!A7 -> 2.19 | B17: DTC Online | C17: =Inputs!A23 -> Fitness & Gym-Goers | D17: =Channel_Economics!D7 -> 1.15649 | E17: =Inputs!C23 -> 6.23 | F17: =IF(D17<=0,0,Inputs!$B$5/D17) -> 38.046157 | G17: =IF(E17=0,0,F17/E17) -> 6.1069273
A18: =Channel_Economics!A7 -> 2.19 | B18: DTC Online | C18: =Inputs!A24 -> On-the-go Commuters | D18: =Channel_Economics!D7 -> 1.15649 | E18: =Inputs!C24 -> 5.87 | F18: =IF(D18<=0,0,Inputs!$B$5/D18) -> 38.046157 | G18: =IF(E18=0,0,F18/E18) -> 6.4814577
A19: =Channel_Economics!A7 -> 2.19 | B19: DTC Online | C19: =Inputs!A25 -> Students & Budget-Conscious | D19: =Channel_Economics!D7 -> 1.15649 | E19: =Inputs!C25 -> 5.1 | F19: =IF(D19<=0,0,Inputs!$B$5/D19) -> 38.046157 | G19: =IF(E19=0,0,F19/E19) -> 7.4600308
A20: =Channel_Economics!A8 -> 2.19 | B20: Gym & Office | C20: =Inputs!A22 -> Urban Wellness Professionals | D20: =Channel_Economics!D8 -> 1.132 | E20: =Inputs!C22 -> 7.56 | F20: =IF(D20<=0,0,Inputs!$B$5/D20) -> 38.869258 | G20: =IF(E20=0,0,F20/E20) -> 5.1414362
A21: =Channel_Economics!A8 -> 2.19 | B21: Gym & Office | C21: =Inputs!A23 -> Fitness & Gym-Goers | D21: =Channel_Economics!D8 -> 1.132 | E21: =Inputs!C23 -> 6.23 | F21: =IF(D21<=0,0,Inputs!$B$5/D21) -> 38.869258 | G21: =IF(E21=0,0,F21/E21) -> 6.2390462
A22: =Channel_Economics!A8 -> 2.19 | B22: Gym & Office | C22: =Inputs!A24 -> On-the-go Commuters | D22: =Channel_Economics!D8 -> 1.132 | E22: =Inputs!C24 -> 5.87 | F22: =IF(D22<=0,0,Inputs!$B$5/D22) -> 38.869258 | G22: =IF(E22=0,0,F22/E22) -> 6.6216794
A23: =Channel_Economics!A8 -> 2.19 | B23: Gym & Office | C23: =Inputs!A25 -> Students & Budget-Conscious | D23: =Channel_Economics!D8 -> 1.132 | E23: =Inputs!C25 -> 5.1 | F23: =IF(D23<=0,0,Inputs!$B$5/D23) -> 38.869258 | G23: =IF(E23=0,0,F23/E23) -> 7.6214231
A24: =Channel_Economics!A9 -> 2.19 | B24: Retail/Grocery | C24: =Inputs!A22 -> Urban Wellness Professionals | D24: =Channel_Economics!D9 -> 0.6283 | E24: =Inputs!C22 -> 7.56 | F24: =IF(D24<=0,0,Inputs!$B$5/D24) -> 70.03024 | G24: =IF(E24=0,0,F24/E24) -> 9.2632593
A25: =Channel_Economics!A9 -> 2.19 | B25: Retail/Grocery | C25: =Inputs!A23 -> Fitness & Gym-Goers | D25: =Channel_Economics!D9 -> 0.6283 | E25: =Inputs!C23 -> 6.23 | F25: =IF(D25<=0,0,Inputs!$B$5/D25) -> 70.03024 | G25: =IF(E25=0,0,F25/E25) -> 11.240809
A26: =Channel_Economics!A9 -> 2.19 | B26: Retail/Grocery | C26: =Inputs!A24 -> On-the-go Commuters | D26: =Channel_Economics!D9 -> 0.6283 | E26: =Inputs!C24 -> 5.87 | F26: =IF(D26<=0,0,Inputs!$B$5/D26) -> 70.03024 | G26: =IF(E26=0,0,F26/E26) -> 11.930194
A27: =Channel_Economics!A9 -> 2.19 | B27: Retail/Grocery | C27: =Inputs!A25 -> Students & Budget-Conscious | D27: =Channel_Economics!D9 -> 0.6283 | E27: =Inputs!C25 -> 5.1 | F27: =IF(D27<=0,0,Inputs!$B$5/D27) -> 70.03024 | G27: =IF(E27=0,0,F27/E27) -> 13.73142
A28: =Channel_Economics!A10 -> 2.59 | B28: DTC Online | C28: =Inputs!A22 -> Urban Wellness Professionals | D28: =Channel_Economics!D10 -> 1.54489 | E28: =Inputs!C22 -> 7.56 | F28: =IF(D28<=0,0,Inputs!$B$5/D28) -> 28.480992 | G28: =IF(E28=0,0,F28/E28) -> 3.767327
A29: =Channel_Economics!A10 -> 2.59 | B29: DTC Online | C29: =Inputs!A23 -> Fitness & Gym-Goers | D29: =Channel_Economics!D10 -> 1.54489 | E29: =Inputs!C23 -> 6.23 | F29: =IF(D29<=0,0,Inputs!$B$5/D29) -> 28.480992 | G29: =IF(E29=0,0,F29/E29) -> 4.5715878
A30: =Channel_Economics!A10 -> 2.59 | B30: DTC Online | C30: =Inputs!A24 -> On-the-go Commuters | D30: =Channel_Economics!D10 -> 1.54489 | E30: =Inputs!C24 -> 5.87 | F30: =IF(D30<=0,0,Inputs!$B$5/D30) -> 28.480992 | G30: =IF(E30=0,0,F30/E30) -> 4.8519578
A31: =Channel_Economics!A10 -> 2.59 | B31: DTC Online | C31: =Inputs!A25 -> Students & Budget-Conscious | D31: =Channel_Economics!D10 -> 1.54489 | E31: =Inputs!C25 -> 5.1 | F31: =IF(D31<=0,0,Inputs!$B$5/D31) -> 28.480992 | G31: =IF(E31=0,0,F31/E31) -> 5.5845083
A32: =Channel_Economics!A11 -> 2.59 | B32: Gym & Office | C32: =Inputs!A22 -> Urban Wellness Professionals | D32: =Channel_Economics!D11 -> 1.452 | E32: =Inputs!C22 -> 7.56 | F32: =IF(D32<=0,0,Inputs!$B$5/D32) -> 30.30303 | G32: =IF(E32=0,0,F32/E32) -> 4.0083373
A33: =Channel_Economics!A11 -> 2.59 | B33: Gym & Office | C33: =Inputs!A23 -> Fitness & Gym-Goers | D33: =Channel_Economics!D11 -> 1.452 | E33: =Inputs!C23 -> 6.23 | F33: =IF(D33<=0,0,Inputs!$B$5/D33) -> 30.30303 | G33: =IF(E33=0,0,F33/E33) -> 4.8640498
A34: =Channel_Economics!A11 -> 2.59 | B34: Gym & Office | C34: =Inputs!A24 -> On-the-go Commuters | D34: =Channel_Economics!D11 -> 1.452 | E34: =Inputs!C24 -> 5.87 | F34: =IF(D34<=0,0,Inputs!$B$5/D34) -> 30.30303 | G34: =IF(E34=0,0,F34/E34) -> 5.1623561
A35: =Channel_Economics!A11 -> 2.59 | B35: Gym & Office | C35: =Inputs!A25 -> Students & Budget-Conscious | D35: =Channel_Economics!D11 -> 1.452 | E35: =Inputs!C25 -> 5.1 | F35: =IF(D35<=0,0,Inputs!$B$5/D35) -> 30.30303 | G35: =IF(E35=0,0,F35/E35) -> 5.9417706
A36: =Channel_Economics!A12 -> 2.59 | B36: Retail/Grocery | C36: =Inputs!A22 -> Urban Wellness Professionals | D36: =Channel_Economics!D12 -> 0.8563 | E36: =Inputs!C22 -> 7.56 | F36: =IF(D36<=0,0,Inputs!$B$5/D36) -> 51.383861 | G36: =IF(E36=0,0,F36/E36) -> 6.796807
A37: =Channel_Economics!A12 -> 2.59 | B37: Retail/Grocery | C37: =Inputs!A23 -> Fitness & Gym-Goers | D37: =Channel_Economics!D12 -> 0.8563 | E37: =Inputs!C23 -> 6.23 | F37: =IF(D37<=0,0,Inputs!$B$5/D37) -> 51.383861 | G37: =IF(E37=0,0,F37/E37) -> 8.2478107
A38: =Channel_Economics!A12 -> 2.59 | B38: Retail/Grocery | C38: =Inputs!A24 -> On-the-go Commuters | D38: =Channel_Economics!D12 -> 0.8563 | E38: =Inputs!C24 -> 5.87 | F38: =IF(D38<=0,0,Inputs!$B$5/D38) -> 51.383861 | G38: =IF(E38=0,0,F38/E38) -> 8.753639
A39: =Channel_Economics!A12 -> 2.59 | B39: Retail/Grocery | C39: =Inputs!A25 -> Students & Budget-Conscious | D39: =Channel_Economics!D12 -> 0.8563 | E39: =Inputs!C25 -> 5.1 | F39: =IF(D39<=0,0,Inputs!$B$5/D39) -> 51.383861 | G39: =IF(E39=0,0,F39/E39) -> 10.075267
A41: Summary — months to payback, using the segment most likely to buy in that channel (Wellness for DTC, Gym-goers for Gym & Office, Students for Retail)
A42: Price (€) | B42: DTC (Wellness) | C42: Gym & Office (Gym-goers) | D42: Retail (Students)
...

Sheet Scenarios
A1: SCENARIOS — Option A vs Option B
A3: Lever / KPI | B3: A — Premium first | C3: B — Volume first | D3: How it is computed
A4: Launch price (€) | B4: =Inputs!C11 -> 2.19 | C4: =Inputs!B11 -> 1.79 | D4: Change to any of the three candidate prices (Inputs row 11)
A5: Price index (1=€1.79, 2=€2.19, 3=€2.59) | B5: 2 | C5: 1 | D5: Drives the lookups below
A6: DTC Online in launch mix? (1/0) | B6: 1 | C6: 1
A7: Gym & Office in launch mix? (1/0) | B7: 1 | C7: 0
A8: Retail/Grocery in launch mix? (1/0) | B8: 0 | C8: 1
A10: Unit economics
A11: Contribution / can — DTC (€) | B11: =INDEX(Channel_Economics!$D$4:$D$12,(B5-1)*3+1) -> 1.15649 | C11: =INDEX(Channel_Economics!$D$4:$D$12,(C5-1)*3+1) -> 0.76809
A12: Contribution / can — Gym & Office (€) | B12: =INDEX(Channel_Economics!$D$4:$D$12,(B5-1)*3+2) -> 1.132 | C12: =INDEX(Channel_Economics!$D$4:$D$12,(C5-1)*3+2) -> 0.812
A13: Contribution / can — Retail (€) | B13: =INDEX(Channel_Economics!$D$4:$D$12,(B5-1)*3+3) -> 0.6283 | C13: =INDEX(Channel_Economics!$D$4:$D$12,(C5-1)*3+3) -> 0.4003
A14: Weighted contribution / can, selected channels (€) | B14: =IF(SUMPRODUCT(B6:B8,Inputs!$F$15:$F$17)=0,0,SUMPRODUCT(B6:B8,Inputs!$F$15:$F$17,B11:B13)/SUMPRODUCT(B6:B8,Inputs!$F$15:$F$17)) -> 1.1476874 | C14: =IF(SUMPRODUCT(C6:C8,Inputs!$F$15:$F$17)=0,0,SUMPRODUCT(C6:C8,Inputs!$F$15:$F$17,C11:C13)/SUMPRODUCT(C6:C8,Inputs!$F$15:$F$17)) -> 0.54320501 | D14: Weights = home-market unit mix of the selected channels (Inputs F15:F17)
A15: Cans to repay CAC (blended) | B15: =IF(B14<=0,0,Inputs!$B$5/B14) -> 38.337967 | C15: =IF(C14<=0,0,Inputs!$B$5/C14) -> 81.000726
A17: Demand side
A18: Reachable share of survey (prefers a selected channel) | B18: =SUMPRODUCT(Inputs!$B$22:$B$25,(Inputs!$E$22:$E$25*B$6+Inputs!$F$22:$F$25*B$7+Inputs!$G$22:$G$25*B$8)) -> 0.536002 | C18: =SUMPRODUCT(Inputs!$B$22:$B$25,(Inputs!$E$22:$E$25*C$6+Inputs!$F$22:$F$25*C$7+Inputs!$G$22:$G$25*C$8)) -> 0.74777 | D18: Σ segment share × share preferring a selected channel
A19: Reachable AND accepts price (hard ceiling) | B19: =SUMPRODUCT(Inputs!$B$22:$B$25,(Inputs!$E$22:$E$25*B$6+Inputs!$F$22:$F$25*B$7+Inputs!$G$22:$G$25*B$8),INDEX(Inputs!$H$22:$J$25,0,B5)) -> 0.46601598 | C19: =SUMPRODUCT(Inputs!$B$22:$B$25,(Inputs!$E$22:$E$25*C$6+Inputs!$F$22:$F$25*C$7+Inputs!$G$22:$G$25*C$8),INDEX(Inputs!$H$22:$J$25,0,C5)) -> 0.74287154 | D19: Row 18 weighted by hard acceptance at chosen price
A20: Reachable AND price feels reasonable (comfort) | B20: =SUMPRODUCT(Inputs!$B$22:$B$25,(Inputs!$E$22:$E$25*B$6+Inputs!$F$22:$F$25*B$7+Inputs!$G$22:$G$25*B$8),INDEX(Inputs!$B$28:$D$31,0,B5)) -> 0.32282332 | C20: =SUMPRODUCT(Inputs!$B$22:$B$25,(Inputs!$E$22:$E$25*C$6+Inputs!$F$22:$F$25*C$7+Inputs!$G$22:$G$25*C$8),INDEX(Inputs!$B$28:$D$31,0,C5)) -> 0.57655716 | D20: Row 18 weighted by comfort acceptance at chosen price
A21: Weighted purchases / month of reached buyers | B21: =IF(B19=0,0,SUMPRODUCT(Inputs!$B$22:$B$25,(Inputs!$E$22:$E$25*B$6+Inputs!$F$22:$F$25*B$7+Inputs!$G$22:$G$25*B$8),INDEX(Inputs!$H$22:$J$25,0,B5),Inputs!$C$22:$C$25)/B19) -> 6.4937138 | C21: =IF(C19=0,0,SUMPRODUCT(Inputs!$B$22:$B$25,(Inputs!$E$22:$E$25*C$6+Inputs!$F$22:$F$25*C$7+Inputs!$G$22:$G$25*C$8),INDEX(Inputs!$H$22:$J$25,0,C5),Inputs!$C$22:$C$25)/C19) -> 6.1950166
A22: CAC payback (months) | B22: =IF(B21=0,0,B15/B21) -> 5.9038584 | C22: =IF(C21=0,0,C15/C21) -> 13.075143 | D22: Cans to repay CAC ÷ purchases per month
A23: Meets CFO ≤18-month test? | B23: =IF(B22<=Payback!$B$47,"Yes","No") -> Yes | C23: =IF(C22<=Payback!$B$47,"Yes","No") -> Yes
A25: What you give up (stated out loud)
A26: Share of survey NOT reachable through the launch channels | B26: =1-B18 -> 0.463998 | C26: =1-C18 -> 0.25223 | D26: 1 − row 18
A27: Share of survey priced out (hard ceiling) | B27: =1-INDEX(Segment_Fit!$C$8:$E$8,1,B5) -> 0.152475 | C27: =1-INDEX(Segment_Fit!$C$8:$E$8,1,C5) -> 0.00642 | D27: 1 − blended hard acceptance at chosen price
A28: Home-market volume share of channels left out | B28: =SUMPRODUCT(1-B6:B8,Inputs!$F$15:$F$17) -> 0.502 | C28: =SUMPRODUCT(1-C6:C8,Inputs!$F$15:$F$17) -> 0.179 | D28: Σ home-market unit mix of channels set to 0
A29: Margin / can given up vs. the other option (€) | B29: =B14-C14 -> 0.60448236 | C29: =C14-B14 -> -0.60448236
A30: Positioning risk | B30: Priced in VoltFit's DTC subscription band (€2.19) — credible premium, but must taste the part ("wellness brands taste like medicine") | C30: Priced between Mate Libre (€1.4–1.8) and VoltFit (€2.1–2.7); in retail, moving up later is very hard once anchored next to PulsUp promos

Sheet Volume_Estimate
A1: VOLUME ESTIMATE — Year 1, Berlin + Munich
A2: Method: home-market per-capita sales × launch-city population × comparability haircut × channel coverage × ramp. Every step is an explicit input on Inputs.
A4: Step | B4: Option A | C4: Option B | D4: Source
A5: Home-market units / capita / yr | B5: =Inputs!D46 -> 0.023118353 | C5: =Inputs!D46 -> 0.023118353 | D5: Inputs — deduplicated sales ÷ population
A6: Launch population (m) | B6: =Inputs!B49+Inputs!B50 -> 5.4 | C6: =Inputs!B49+Inputs!B50 -> 5.4 | D6: Berlin + Munich
A7: Steady-state units at home-market penetration | B7: =B5*B6*1000000 -> 124839.1 | C7: =C5*C6*1000000 -> 124839.1
A8: Comparability factor | B8: =Inputs!B51 -> 0.8 | C8: =Inputs!B51 -> 0.8 | D8: ASSUMPTION — see Inputs B51
A9: Channel coverage (home-market mix of selected channels) | B9: =SUMPRODUCT(Scenarios!B6:B8,Inputs!F15:F17) -> 0.498 | C9: =SUMPRODUCT(Scenarios!C6:C8,Inputs!F15:F17) -> 0.821
A10: Price acceptance adj. (hard, reached segments) vs €1.79 base | B10: =IF(Scenarios!B18=0,0,Scenarios!B19/Scenarios!B18) -> 0.86942955 | C10: =IF(Scenarios!C18=0,0,Scenarios!C19/Scenarios!C18) -> 0.99344924 | D10: Home markets sell at €1.35; a higher German price loses the priced-out share of reached segments
A11: Year-1 ramp | B11: =Inputs!B52 -> 0.6 | C11: =Inputs!B52 -> 0.6
A12: Year-1 units | B12: =B7*B8*B9*B10*B11 -> 25945.116 | C12: =C7*C8*C9*C10*C11 -> 48874.319
A13: Weighted net price to LUMEN (€) | B13: =IF((Scenarios!B6*Inputs!$F$15+Scenarios!B7*Inputs!$F$16+Scenarios!B8*Inputs!$F$17)=0,0,(Scenarios!B6*Inputs!$F$15*INDEX(Channel_Economics!$C$4:$C$12,(Scenarios!B5-1)*3+1)+Scenarios!B7*Inputs!$F$16*INDEX(Channel_Economics!$C$4:$C$12,(Scenarios!B5-1)*3+2)+Scenarios!B8*Inputs!$F$17*INDEX(Channel_Economics!$C$4:$C$12,(Scenarios!B5-1)*3+3))/(Scenarios!B6*Inputs!$F$15+Scenarios!B7*Inputs!$F$16+Scenarios!B8*Inputs!$F$17)) -> 1.7676874 | C13: =IF((Scenarios!C6*Inputs!$F$15+Scenarios!C7*Inputs!$F$16+Scenarios!C8*Inputs!$F$17)=0,0,(Scenarios!C6*Inputs!$F$15*INDEX(Channel_Economics!$C$4:$C$12,(Scenarios!C5-1)*3+1)+Scenarios!C7*Inputs!$F$16*INDEX(Channel_Economics!$C$4:$C$12,(Scenarios!C5-1)*3+2)+Scenarios!C8*Inputs!$F$17*INDEX(Channel_Economics!$C$4:$C$12,(Scenarios!C5-1)*3+3))/(Scenarios!C6*Inputs!$F$15+Scenarios!C7*Inputs!$F$16+Scenarios!C8*Inputs!$F$17)) -> 1.163205
A14: Year-1 net revenue to LUMEN (€) | B14: =B12*B13 -> 45862.854 | C14: =C12*C13 -> 56850.853
A15: Year-1 contribution after COGS (€) | B15: =B12*Scenarios!B14 -> 29776.882 | C15: =C12*Scenarios!C14 -> 26548.775
A16: Year-1 marketing budget (€) | B16: =Inputs!B54 -> 97960.786 | C16: =Inputs!B54 -> 97960.786
A17: Year-1 contribution after marketing (€) | B17: =B15-B16 -> -68183.904 | C17: =C15-C16 -> -71412.011
A18: Customers the budget can acquire at blended CAC | B18: =Inputs!B54/Inputs!B5 -> 2226.3815 | C18: =Inputs!B54/Inputs!B5 -> 2226.3815
A20: Sensitivity — Year-1 units vs comparability factor (Option A / Option B)
A21: Comparability factor | B21: Option A units | C21: Option B units
A22: 0.5 | B22: =$B$7*A22*$B$9*$B$10*$B$11 -> 16215.698 | C22: =$C$7*A22*$C$9*$C$10*$C$11 -> 30546.449
A23: 0.65 | B23: =$B$7*A23*$B$9*$B$10*$B$11 -> 21080.407 | C23: =$C$7*A23*$C$9*$C$10*$C$11 -> 39710.384
A24: 0.8 | B24: =$B$7*A24*$B$9*$B$10*$B$11 -> 25945.116 | C24: =$C$7*A24*$C$9*$C$10*$C$11 -> 48874.319
A25: 1 | B25: =$B$7*A25*$B$9*$B$10*$B$11 -> 32431.395 | C25: =$C$7*A25*$C$9*$C$10*$C$11 -> 61092.899
A26: 1.2 | B26: =$B$7*A26*$B$9*$B$10*$B$11 -> 38917.674 | C26: =$C$7*A26*$C$9*$C$10*$C$11 -> 73311.479
A28: Caveat: this is a per-capita transfer, not a demand model. It says "if Germans in Berlin/Munich bought like the Dutch, Danes and Swedes, adjusted", nothing more. The brief asks for responsible estimation, not precision — keep the assumptions visible.

Sheet Seasonality
A1: SEASONALITY & LAUNCH TIMING
A3: Month | B3: DE seasonality index | C3: Avg temp DE (°C) | D3: Home-market index (NL/DK/SE) | E3: Gap DE − home
A4: 1 | B4: 78 | C4: 2 | D4: 73 | E4: =B4-D4 -> 5
A5: 2 | B5: 80 | C5: 3 | D5: 76 | E5: =B5-D5 -> 4
A6: 3 | B6: 88 | C6: 7 | D6: 85 | E6: =B6-D6 -> 3
A7: 4 | B7: 98 | C7: 11 | D7: 98 | E7: =B7-D7 -> 0
A8: 5 | B8: 118 | C8: 15 | D8: 120 | E8: =B8-D8 -> -2
A9: 6 | B9: 132 | C9: 18 | D9: 136 | E9: =B9-D9 -> -4
A10: 7 | B10: 138 | C10: 19 | D10: 134 | E10: =B10-D10 -> 4
A11: 8 | B11: 128 | C11: 19 | D11: 119 | E11: =B11-D11 -> 9
A12: 9 | B12: 104 | C12: 15 | D12: 100 | E12: =B12-D12 -> 4
A13: 10 | B13: 90 | C13: 11 | D13: 90 | E13: =B13-D13 -> 0
A14: 11 | B14: 82 | C14: 6 | D14: 83 | E14: =B14-D14 -> -1
A15: 12 | B15: 84 | C15: 3 | D15: 86 | E15: =B15-D15 -> -2
A17: Correlation DE index vs home-market index | B17: =CORREL(B4:B15,D4:D15) -> 0.98542896
A18: Correlation DE index vs temperature | B18: =CORREL(B4:B15,C4:C15) -> 0.94523062
A20: Reading: the German seasonality curve and LUMEN's own home-market curve are nearly identical (correlation ~0.99) — the seasonality transfer is the one assumption in this case that IS supported by data. Launch in April–May: index rises from 98 to 138 by July, so distribution is in place before peak demand. Competitor promo activity (competitor_price_history.csv) is sparse and mostly winter (Feb) or summer (Jun–Jul), so a spring launch avoids both clusters.

Sheet Data_Quality
A1: DATA QUALITY — issues found and how they were handled
A3: File | B3: Issue | C3: Handling
A4: historical_sales_weekly.csv | B4: 4 exact duplicate rows: NL 2025-07-14, DK 2025-09-22, DK 2025-12-22, NL 2026-04-27 (706 rows → 702 unique). | C4: Dropped before any aggregation. All home-market figures in this model use the deduplicated file.
A5: historical_sales_weekly.csv | B5: README announces "an unusual spike week". The highest weeks (late July 2025, June 2026) are all summer and consistent with the seasonality index; no single week exceeds 3σ. | C5: Not treated as an anomaly. Stated explicitly rather than invented.
A6: LUMEN_Case_Brief.md vs data | B6: Brief says home markets generate "roughly €3.2M trailing revenue". The data room sums to €1.62M over 78 weeks (€1.08M annualised) at €1.35 retail booked as revenue. | C6: Flagged as an inconsistency. Model uses the data-room figure for per-capita transfer; the brief figure is not reproducible from the files.
A7: price_test_results.csv vs survey | B7: Headline acceptance (61.7/51.7/26.7%) is a blended figure. Recomputed from price_sensitivity_survey.csv it reproduces approximately (77/52/25% "comfort"), and splits very unevenly by segment. | C7: Both blended and per-segment acceptance shown (Segment_Fit). The segment split is the core finding.
A8: customer_survey.csv | B8: Contains first_name, last_name, email (synthetic). | C8: Columns never loaded into the model or the tool. Only segment, city, frequency, spend, sensitivity, channel preference, awareness, intent are used.
A9: market_context.csv | B9: Regional split is labelled "illustrative" in the notes column. | C9: Used for city prioritisation only; not treated as measured data.
A10: marketing_funnel_monthly.csv | B10: LTV:CAC by channel is 2.7–2.9x, below the 3:1 target stated in the brief. | C10: Reported as-is; the 3:1 target is treated as a plan assumption, not an observed fact.
